Workbook

Sheet Sales summary
B2: Monthly Sales Summary — Tankhoone Fashion Retail 2023
B3: Row Labels | C3: Sum of Revenue | D3: Count of Order_ID | E3: Sum of Qty
B4: Jan | C4: 40415250 | D4: 65 | E4: 138
B5: Feb | C5: 31895200 | D5: 68 | E5: 124
B6: Mar | C6: 83066250 | D6: 164 | E6: 302
B7: Apr | C7: 41159750 | D7: 90 | E7: 149
B8: May | C8: 32219750 | D8: 75 | E8: 125
B9: Jun | C9: 45394750 | D9: 89 | E9: 171
B10: Jul | C10: 50704600 | D10: 111 | E10: 189
B11: Aug | C11: 25137150 | D11: 55 | E11: 110
B12: Sep | C12: 56522300 | D12: 109 | E12: 218
B13: Oct | C13: 52349700 | D13: 99 | E13: 188
B14: Nov | C14: 68497050 | D14: 119 | E14: 239
B15: Dec | C15: 66352550 | D15: 145 | E15: 248
B16: Grand Total | C16: 593714300 | D16: 1189 | E16: 2201

Sheet Sales by Categories
B5: Sales by Categories
T8: Co-ord Sets | U8: 193451000
T9: Sweatshirts | U9: 110068750
T10: Dresses | U10: 76313750
B11: Row Labels | C11: Sum of Revenue | D11: Sum of Qty | T11: Knitwear | U11: 53918500
B12: Co-ord Sets | C12: 193451000 | D12: 466 | T12: Outerwear | U12: 49078750
B13: Sweatshirts | C13: 110068750 | D13: 518 | T13: Shirts | U13: 28173300
B14: Dresses | C14: 76313750 | D14: 251 | T14: Knit Dresses | U14: 25104000
B15: Knitwear | C15: 53918500 | D15: 206 | T15: Basics | U15: 19661250
B16: Outerwear | C16: 49078750 | D16: 129 | T16: Skirts | U16: 18708500
B17: Shirts | C17: 28173300 | D17: 148 | T17: Pyjamas | U17: 11001000
B18: Knit Dresses | C18: 25104000 | D18: 80 | T18: Bottoms | U18: 8235500
B19: Basics | C19: 19661250 | D19: 193
B20: Skirts | C20: 18708500 | D20: 113
B21: Pyjamas | C21: 11001000 | D21: 50
B22: Bottoms | C22: 8235500 | D22: 47
B23: Grand Total | C23: 593714300 | D23: 2201

Sheet Sales by Channel
C1: Sales by Channel
B5: Row Labels | C5: Sum of Revenue
B6: Instagram DM | C6: 233673800
B7: in-store | C7: 171736900
B8: Website | C8: 94536600
B9: Telegram | C9: 68506800
B10: Grand Total | C10: 568454100

Sheet Top 10 SKUs by Revenue
D2: Top 10 SKUs by Revenue
C8: Row Labels | D8: Sum of Revenue | E8: Sum of Qty
C9: Beige Co-ord Set | D9: 69678000 | E9: 172
C10: Sage Green Co-ord | D10: 51621500 | E10: 124 | O10: Beige Co-ord Set | P10: 69678000
C11: Orange Linen Set | D11: 50094000 | E11: 117 | O11: Sage Green Co-ord | P11: 51621500
C12: Khaki Cargo Jacket | D12: 49078750 | E12: 129 | O12: Orange Linen Set | P12: 50094000
C13: Pink Sweatshirt | D13: 40513000 | E13: 190 | O13: Khaki Cargo Jacket | P13: 49078750
C14: Olive Sweatshirt | D14: 27563000 | E14: 132 | O14: Pink Sweatshirt | P14: 40513000
C15: Floral Print Dress | D15: 27494000 | E15: 96 | O15: Olive Sweatshirt | P15: 27563000
C16: Burgundy Knit Dress | D16: 25104000 | E16: 80 | O16: Floral Print Dress | P16: 27494000
C17: Cable Knit Vest White | D17: 25012000 | E17: 98 | O17: Burgundy Knit Dress | P17: 25104000
C18: Rust Co-ord Set | D18: 22057500 | E18: 53 | O18: Cable Knit Vest White | P18: 25012000
C19: Grand Total | D19: 388215750 | E19: 1191 | O19: Rust Co-ord Set | P19: 22057500

Sheet Demand Analysis
B2: Sum of Qty | C2: Column Labels
B3: Row Labels | C3: Jan | D3: Feb | E3: Mar | F3: Apr | G3: May | H3: Jun | I3: Jul | J3: Aug | K3: Sep | L3: Oct | M3: Nov | N3: Dec | O3: Grand Total | R3: Row Labels | S3: Jan | T3: Feb | U3: Mar | V3: Apr | W3: May | X3: Jun | Y3: Jul | Z3: Aug | AA3: Sep | AB3: Oct | AC3: Nov | AD3: Dec | AE3: Average Monthly Qty | AF3: Std Dev | AG3: CV | AH3: CV Flag | AI3: Category | AJ3: Slope | AK3: Trend Flag | AM3: Category | AN3: Avg CV | AO3: Count High
B4: PRD-001 | C4: 1 | D4: 3 | E4: 9 | F4: 5 | G4: 1 | H4: 7 | I4: 3 | K4: 5 | L4: 4 | M4: 1 | N4: 2 | O4: 41 | R4: PRD-001 | S4: 1 | T4: 3 | U4: 9 | V4: 5 | W4: 1 | X4: 7 | Y4: 3 | AA4: 5 | AB4: 4 | AC4: 1 | AD4: 2 | AE4: =AVERAGE(S4:AD4) -> 3.7272727 | AF4: =_xlfn.STDEV.P(S4:AD4) -> 2.489648 | AG4: =AF4/AE4 -> 0.66795434 | AH4: =IF(AG4>0.6, "High",IF(AG4>0.3, "Moderate","Stable")) -> High | AI4: =_xlfn.XLOOKUP(R4,Table1[SKU_Code],Table1[Category],"Missing") -> Co-ord Sets | AJ4: =SLOPE(Table17[[#This Row],[Jan]:[Dec]], {1,2,3,4,5,6,7,8,9,10,11,12}) -> -0.13454075 | AK4: =IF(Table17[[#This Row],[Slope]]>5,"Growing", IF(Table17[[#This Row],[Slope]]<-5,"Declining","Flat")) -> Flat | AM4: {=_xlfn.UNIQUE(Table17[Category])} -> Co-ord Sets | AN4: =AVERAGEIF(Table17[Category],AM4,Table17[CV]) -> 0.65747489 | AO4: =COUNTIFS(Table17[Category],AM4,Table17[CV Flag],"High") -> 6
B5: PRD-002 | C5: 2 | D5: 6 | E5: 11 | F5: 1 | G5: 10 | H5: -1 | I5: 5 | J5: 2 | K5: 5 | L5: 11 | M5: 12 | N5: 5 | O5: 69 | R5: PRD-002 | S5: 2 | T5: 6 | U5: 11 | V5: 1 | W5: 10 | X5: -1 | Y5: 5 | Z5: 2 | AA5: 5 | AB5: 11 | AC5: 12 | AD5: 5 | AE5: =AVERAGE(S5:AD5) -> 5.75 | AF5: =_xlfn.STDEV.P(S5:AD5) -> 4.1857895 | AG5: =AF5/AE5 -> 0.72796338 | AH5: =IF(AG5>0.6, "High",IF(AG5>0.3, "Moderate","Stable")) -> High | AI5: =_xlfn.XLOOKUP(R5,Table1[SKU_Code],Table1[Category],"Missing") -> Co-ord Sets | AJ5: =SLOPE(Table17[[#This Row],[Jan]:[Dec]], {1,2,3,4,5,6,7,8,9,10,11,12}) -> 0.31118881 | AK5: =IF(Table17[[#This Row],[Slope]]>5,"Growing", IF(Table17[[#This Row],[Slope]]<-5,"Declining","Flat")) -> Flat | AM5: Sweatshirts | AN5: =AVERAGEIF(Table17[Category],AM5,Table17[CV]) -> 0.75941829 | AO5: =COUNTIFS(Table17[Category],AM5,Table17[CV Flag],"High") -> 6
B6: PRD-003 | D6: 5 | E6: 14 | F6: 1 | G6: 2 | H6: 10 | I6: 3 | J6: 3 | K6: 6 | L6: 3 | M6: 8 | N6: 7 | O6: 62 | R6: PRD-003 | T6: 5 | U6: 14 | V6: 1 | W6: 2 | X6: 10 | Y6: 3 | Z6: 3 | AA6: 6 | AB6: 3 | AC6: 8 | AD6: 7 | AE6: =AVERAGE(S6:AD6) -> 5.6363636 | AF6: =_xlfn.STDEV.P(S6:AD6) -> 3.7239453 | AG6: =AF6/AE6 -> 0.66069997 | AH6: =IF(AG6>0.6, "High",IF(AG6>0.3, "Moderate","Stable")) -> High | AI6: =_xlfn.XLOOKUP(R6,Table1[SKU_Code],Table1[Category],"Missing") -> Co-ord Sets | AJ6: =SLOPE(Table17[[#This Row],[Jan]:[Dec]], {1,2,3,4,5,6,7,8,9,10,11,12}) -> -0.063636364 | AK6: =IF(Table17[[#This Row],[Slope]]>5,"Growing", IF(Table17[[#This Row],[Slope]]<-5,"Declining","Flat")) -> Flat | AM6: Knit Dresses | AN6: =AVERAGEIF(Table17[Category],AM6,Table17[CV]) -> 0.86292695 | AO6: =COUNTIFS(Table17[Category],AM6,Table17[CV Flag],"High") -> 2
B7: PRD-004 | D7: 3 | E7: 1 | F7: 5 | G7: 9 | H7: 3 | I7: 3 | J7: 9 | K7: 3 | L7: 11 | M7: 9 | N7: 7 | O7: 63 | R7: PRD-004 | T7: 3 | U7: 1 | V7: 5 | W7: 9 | X7: 3 | Y7: 3 | Z7: 9 | AA7: 3 | AB7: 11 | AC7: 9 | AD7: 7 | AE7: =AVERAGE(S7:AD7) -> 5.7272727 | AF7: =_xlfn.STDEV.P(S7:AD7) -> 3.2218264 | AG7: =AF7/AE7 -> 0.56254112 | AH7: =IF(AG7>0.6, "High",IF(AG7>0.3, "Moderate","Stable")) -> Moderate | AI7: =_xlfn.XLOOKUP(R7,Table1[SKU_Code],Table1[Category],"Missing") -> Sweatshirts | AJ7: =SLOPE(Table17[[#This Row],[Jan]:[Dec]], {1,2,3,4,5,6,7,8,9,10,11,12}) -> 0.58181818 | AK7: =IF(Table17[[#This Row],[Slope]]>5,"Growing", IF(Table17[[#This Row],[Slope]]<-5,"Declining","Flat")) -> Flat | AM7: Knitwear | AN7: =AVERAGEIF(Table17[Category],AM7,Table17[CV]) -> 0.69132162 | AO7: =COUNTIFS(Table17[Category],AM7,Table17[CV Flag],"High") -> 4
B8: PRD-005 | C8: 1 | D8: 8 | E8: 8 | F8: 3 | H8: 2 | I8: 6 | J8: 12 | K8: 15 | M8: 5 | N8: 8 | O8: 68 | R8: PRD-005 | S8: 1 | T8: 8 | U8: 8 | V8: 3 | X8: 2 | Y8: 6 | Z8: 12 | AA8: 15 | AC8: 5 | AD8: 8 | AE8: =AVERAGE(S8:AD8) -> 6.8 | AF8: =_xlfn.STDEV.P(S8:AD8) -> 4.1665333 | AG8: =AF8/AE8 -> 0.61272549 | AH8: =IF(AG8>0.6, "High",IF(AG8>0.3, "Moderate","Stable")) -> High | AI8: =_xlfn.XLOOKUP(R8,Table1[SKU_Code],Table1[Category],"Missing") -> Sweatshirts | AJ8: =SLOPE(Table17[[#This Row],[Jan]:[Dec]], {1,2,3,4,5,6,7,8,9,10,11,12}) -> 0.47306792 | AK8: =IF(Table17[[#This Row],[Slope]]>5,"Growing", IF(Table17[[#This Row],[Slope]]<-5,"Declining","Flat")) -> Flat | AM8: Shirts | AN8: =AVERAGEIF(Table17[Category],AM8,Table17[CV]) -> 0.68341424 | AO8: =COUNTIFS(Table17[Category],AM8,Table17[CV Flag],"High") -> 3
B9: PRD-006 | C9: 8 | D9: 4 | E9: 14 | F9: 3 | G9: 3 | H9: 5 | I9: -2 | J9: 2 | K9: 9 | L9: 3 | M9: 4 | N9: 6 | O9: 59 | R9: PRD-006 | S9: 8 | T9: 4 | U9: 14 | V9: 3 | W9: 3 | X9: 5 | Y9: -2 | Z9: 2 | AA9: 9 | AB9: 3 | AC9: 4 | AD9: 6 | AE9: =AVERAGE(S9:AD9) -> 4.9166667 | AF9: =_xlfn.STDEV.P(S9:AD9) -> 3.8613109 | AG9: =AF9/AE9 -> 0.78535138 | AH9: =IF(AG9>0.6, "High",IF(AG9>0.3, "Moderate","Stable")) -> High | AI9: =_xlfn.XLOOKUP(R9,Table1[SKU_Code],Table1[Category],"Missing") -> Sweatshirts | AJ9: =SLOPE(Table17[[#This Row],[Jan]:[Dec]], {1,2,3,4,5,6,7,8,9,10,11,12}) -> -0.27622378 | AK9: =IF(Table17[[#This Row],[Slope]]>5,"Growing", IF(Table17[[#This Row],[Slope]]<-5,"Declining","Flat")) -> Flat | AM9: Skirts | AN9: =AVERAGEIF(Table17[Category],AM9,Table17[CV]) -> 0.57864058 | AO9: =COUNTIFS(Table17[Category],AM9,Table17[CV Flag],"High") -> 1
B10: PRD-007 | C10: 4 | D10: 4 | E10: 3 | G10: 5 | H10: 7 | I10: 12 | J10: 2 | K10: 6 | L10: 10 | M10: 2 | N10: 3 | O10: 58 | R10: PRD-007 | S10: 4 | T10: 4 | U10: 3 | W10: 5 | X10: 7 | Y10: 12 | Z10: 2 | AA10: 6 | AB10: 10 | AC10: 2 | AD10: 3 | AE10: =AVERAGE(S10:AD10) -> 5.2727273 | AF10: =_xlfn.STDEV.P(S10:AD10) -> 3.1069105 | AG10: =AF10/AE10 -> 0.58924164 | AH10: =IF(AG10>0.6, "High",IF(AG10>0.3, "Moderate","Stable")) -> Moderate | AI10: =_xlfn.XLOOKUP(R10,Table1[SKU_Code],Table1[Category],"Missing") -> Sweatshirts | AJ10: =SLOPE(Table17[[#This Row],[Jan]:[Dec]], {1,2,3,4,5,6,7,8,9,10,11,12}) -> 0.072096128 | AK10: =IF(Table17[[#This Row],[Slope]]>5,"Growing", IF(Table17[[#This Row],[Slope]]<-5,"Declining","Flat")) -> Flat | AM10: Dresses | AN10: =AVERAGEIF(Table17[Category],AM10,Table17[CV]) -> 0.71883969 | AO10: =COUNTIFS(Table17[Category],AM10,Table17[CV Flag],"High") -> 5
B11: PRD-008 | C11: 4 | D11: 17 | E11: 8 | F11: 6 | H11: 2 | I11: 12 | J11: 3 | K11: 2 | L11: 4 | M11: 13 | N11: 3 | O11: 74 | R11: PRD-008 | S11: 4 | T11: 17 | U11: 8 | V11: 6 | X11: 2 | Y11: 12 | Z11: 3 | AA11: 2 | AB11: 4 | AC11: 13 | AD11: 3 | AE11: =AVERAGE(S11:AD11) -> 6.7272727 | AF11: =_xlfn.STDEV.P(S11:AD11) -> 4.8820806 | AG11: =AF11/AE11 -> 0.72571468 | AH11: =IF(AG11>0.6, "High",IF(AG11>0.3, "Moderate","Stable")) -> High | AI11: =_xlfn.XLOOKUP(R11,Table1[SKU_Code],Table1[Category],"Missing") -> Sweatshirts | AJ11: =SLOPE(Table17[[#This Row],[Jan]:[Dec]], {1,2,3,4,5,6,7,8,9,10,11,12}) -> -0.34217335 | AK11: =IF(Table17[[#This Row],[Slope]]>5,"Growing", IF(Table17[[#This Row],[Slope]]<-5,"Declining","Flat")) -> Flat | AM11: Outerwear | AN11: =AVERAGEIF(Table17[Category],AM11,Table17[CV]) -> 0.7685986 | AO11: =COUNTIFS(Table17[Category],AM11,Table17[CV Flag],"High") -> 1
B12: PRD-009 | C12: 5 | D12: 3 | E12: 3 | F12: 2 | G12: 12 | H12: 10 | I12: 6 | K12: 9 | L12: 3 | M12: 11 | N12: 7 | O12: 71 | R12: PRD-009 | S12: 5 | T12: 3 | U12: 3 | V12: 2 | W12: 12 | X12: 10 | Y12: 6 | AA12: 9 | AB12: 3 | AC12: 11 | AD12: 7 | AE12: =AVERAGE(S12:AD12) -> 6.4545455 | AF12: =_xlfn.STDEV.P(S12:AD12) -> 3.4208887 | AG12: =AF12/AE12 -> 0.52999684 | AH12: =IF(AG12>0.6, "High",IF(AG12>0.3, "Moderate","Stable")) -> Moderate | AI12: =_xlfn.XLOOKUP(R12,Table1[SKU_Code],Table1[Category],"Missing") -> Sweatshirts | AJ12: =SLOPE(Table17[[#This Row],[Jan]:[Dec]], {1,2,3,4,5,6,7,8,9,10,11,12}) -> 0.385511 | AK12: =IF(Table17[[#This Row],[Slope]]>5,"Growing", IF(Table17[[#This Row],[Slope]]<-5,"Declining","Flat")) -> Flat | AM12: Pyjamas | AN12: =AVERAGEIF(Table17[Category],AM12,Table17[CV]) -> 0.91214034 | AO12: =COUNTIFS(Table17[Category],AM12,Table17[CV Flag],"High") -> 1
B13: PRD-010 | C13: 4 | D13: 2 | E13: 1 | F13: 0 | G13: 5 | H13: 8 | I13: 2 | J13: 2 | K13: 7 | L13: 4 | M13: 5 | O13: 40 | R13: PRD-010 | S13: 4 | T13: 2 | U13: 1 | V13: 0 | W13: 5 | X13: 8 | Y13: 2 | Z13: 2 | AA13: 7 | AB13: 4 | AC13: 5 | AE13: =AVERAGE(S13:AD13) -> 3.6363636 | AF13: =_xlfn.STDEV.P(S13:AD13) -> 2.3845231 | AG13: =AF13/AE13 -> 0.65574385 | AH13: =IF(AG13>0.6, "High",IF(AG13>0.3, "Moderate","Stable")) -> High | AI13: =_xlfn.XLOOKUP(R13,Table1[SKU_Code],Table1[Category],"Missing") -> Sweatshirts | AJ13: =SLOPE(Table17[[#This Row],[Jan]:[Dec]], {1,2,3,4,5,6,7,8,9,10,11,12}) -> 0.29090909 | AK13: =IF(Table17[[#This Row],[Slope]]>5,"Growing", IF(Table17[[#This Row],[Slope]]<-5,"Declining","Flat")) -> Flat | AM13: Basics | AN13: =AVERAGEIF(Table17[Category],AM13,Table17[CV]) -> 0.65234596 | AO13: =COUNTIFS(Table17[Category],AM13,Table17[CV Flag],"High") -> 2
B14: PRD-011 | C14: 7 | D14: 3 | E14: 2 | F14: 1 | I14: -3 | J14: 3 | K14: 8 | L14: 8 | M14: 7 | N14: 2 | O14: 38 | R14: PRD-011 | S14: 7 | T14: 3 | U14: 2 | V14: 1 | Y14: -3 | Z14: 3 | AA14: 8 | AB14: 8 | AC14: 7 | AD14: 2 | AE14: =AVERAGE(S14:AD14) -> 3.8 | AF14: =_xlfn.STDEV.P(S14:AD14) -> 3.4292856 | AG14: =AF14/AE14 -> 0.90244359 | AH14: =IF(AG14>0.6, "High",IF(AG14>0.3, "Moderate","Stable")) -> High | AI14: =_xlfn.XLOOKUP(R14,Table1[SKU_Code],Table1[Category],"Missing") -> Knit Dresses | AJ14: =SLOPE(Table17[[#This Row],[Jan]:[Dec]], {1,2,3,4,5,6,7,8,9,10,11,12}) -> 0.17416131 | AK14: =IF(Table17[[#This Row],[Slope]]>5,"Growing", IF(Table17[[#This Row],[Slope]]<-5,"Declining","Flat")) -> Flat | AM14: Bottoms | AN14: =AVERAGEIF(Table17[Category],AM14,Table17[CV]) -> 0.60778114 | AO14: =COUNTIFS(Table17[Category],AM14,Table17[CV Flag],"High") -> 1
B15: PRD-012 | C15: 4 | E15: 2 | F15: 13 | H15: 3 | I15: 7 | J15: 2 | K15: 6 | L15: 2 | M15: 2 | N15: 1 | O15: 42 | R15: PRD-012 | S15: 4 | U15: 2 | V15: 13 | X15: 3 | Y15: 7 | Z15: 2 | AA15: 6 | AB15: 2 | AC15: 2 | AD15: 1 | AE15: =AVERAGE(S15:AD15) -> 4.2 | AF15: =_xlfn.STDEV.P(S15:AD15) -> 3.4583233 | AG15: =AF15/AE15 -> 0.82341031 | AH15: =IF(AG15>0.6, "High",IF(AG15>0.3, "Moderate","Stable")) -> High | AI15: =_xlfn.XLOOKUP(R15,Table1[SKU_Code],Table1[Category],"Missing") -> Knit Dresses | AJ15: =SLOPE(Table17[[#This Row],[Jan]:[Dec]], {1,2,3,4,5,6,7,8,9,10,11,12}) -> -0.38665526 | AK15: =IF(Table17[[#This Row],[Slope]]>5,"Growing", IF(Table17[[#This Row],[Slope]]<-5,"Declining","Flat")) -> Flat
B16: PRD-013 | C16: 4 | D16: 6 | E16: 5 | F16: 6 | G16: 0 | H16: 1 | I16: 8 | J16: 5 | K16: 2 | L16: 10 | M16: 10 | N16: 4 | O16: 61 | R16: PRD-013 | S16: 4 | T16: 6 | U16: 5 | V16: 6 | W16: 0 | X16: 1 | Y16: 8 | Z16: 5 | AA16: 2 | AB16: 10 | AC16: 10 | AD16: 4 | AE16: =AVERAGE(S16:AD16) -> 5.0833333 | AF16: =_xlfn.STDEV.P(S16:AD16) -> 3.0675271 | AG16: =AF16/AE16 -> 0.60344794 | AH16: =IF(AG16>0.6, "High",IF(AG16>0.3, "Moderate","Stable")) -> High | AI16: =_xlfn.XLOOKUP(R16,Table1[SKU_Code],Table1[Category],"Missing") -> Knitwear | AJ16: =SLOPE(Table17[[#This Row],[Jan]:[Dec]], {1,2,3,4,5,6,7,8,9,10,11,12}) -> 0.25524476 | AK16: =IF(Table17[[#This Row],[Slope]]>5,"Growing", IF(Table17[[#This Row],[Slope]]<-5,"Declining","Flat")) -> Flat
B17: PRD-014 | C17: 3 | D17: 3 | E17: 2 | F17: 9 | G17: 5 | H17: 1 | I17: 15 | J17: 3 | K17: 8 | N17: 6 | O17: 55 | R17: PRD-014 | S17: 3 | T17: 3 | U17: 2 | V17: 9 | W17: 5 | X17: 1 | Y17: 15 | Z17: 3 | AA17: 8 | AD17: 6 | AE17: =AVERAGE(S17:AD17) -> 5.5 | AF17: =_xlfn.STDEV.P(S17:AD17) -> 4.0062451 | AG17: =AF17/AE17 -> 0.7284082 | AH17: =IF(AG17>0.6, "High",IF(AG17>0.3, "Moderate","Stable")) -> High | AI17: =_xlfn.XLOOKUP(R17,Table1[SKU_Code],Table1[Category],"Missing") -> Knitwear | AJ17: =SLOPE(Table17[[#This Row],[Jan]:[Dec]], {1,2,3,4,5,6,7,8,9,10,11,12}) -> 0.39865514 | AK17: =IF(Table17[[#This Row],[Slope]]>5,"Growing", IF(Table17[[#This Row],[Slope]]<-5,"Declining","Flat")) -> Flat
B18: PRD-015 | C18: 0 | D18: 5 | E18: 8 | F18: 2 | G18: 6 | I18: 1 | J18: 3 | L18: 5 | M18: 10 | N18: 3 | O18: 43 | R18: PRD-015 | S18: 0 | T18: 5 | U18: 8 | V18: 2 | W18: 6 | Y18: 1 | Z18: 3 | AB18: 5 | AC18: 10 | AD18: 3 | AE18: =AVERAGE(S18:AD18) -> 4.3 | AF18: =_xlfn.STDEV.P(S18:AD18) -> 2.9681644 | AG18: =AF18/AE18 -> 0.69027079 | AH18: =IF(AG18>0.6, "High",IF(AG18>0.3, "Moderate","Stable")) -> High | AI18: =_xlfn.XLOOKUP(R18,Table1[SKU_Code],Table1[Category],"Missing") -> Knitwear | AJ18: =SLOPE(Table17[[#This Row],[Jan]:[Dec]], {1,2,3,4,5,6,7,8,9,10,11,12}) -> 0.20646583 | AK18: =IF(Table17[[#This Row],[Slope]]>5,"Growing", IF(Table17[[#This Row],[Slope]]<-5,"Declining","Flat")) -> Flat
B19: PRD-016 | C19: 3 | D19: 1 | E19: 9 | F19: 2 | G19: 3 | H19: 1 | I19: 2 | J19: 1 | K19: 4 | L19: 2 | M19: 2 | N19: 9 | O19: 39 | R19: PRD-016 | S19: 3 | T19: 1 | U19: 9 | V19: 2 | W19: 3 | X19: 1 | Y19: 2 | Z19: 1 | AA19: 4 | AB19: 2 | AC19: 2 | AD19: 9 | AE19: =AVERAGE(S19:AD19) -> 3.25 | AF19: =_xlfn.STDEV.P(S19:AD19) -> 2.7118567 | AG19: =AF19/AE19 -> 0.83441744 | AH19: =IF(AG19>0.6, "High",IF(AG19>0.3, "Moderate","Stable")) -> High | AI19: =_xlfn.XLOOKUP(R19,Table1[SKU_Code],Table1[Category],"Missing") -> Sweatshirts | AJ19: =SLOPE(Table17[[#This Row],[Jan]:[Dec]], {1,2,3,4,5,6,7,8,9,10,11,12}) -> 0.10839161 | AK19: =IF(Table17[[#This Row],[Slope]]>5,"Growing", IF(Table17[[#This Row],[Slope]]<-5,"Declining","Flat")) -> Flat
B20: PRD-017 | C20: 2 | D20: 1 | E20: 22 | G20: 1 | H20: 1 | I20: 8 | J20: 1 | K20: 2 | L20: 6 | M20: -4 | N20: 6 | O20: 46 | R20: PRD-017 | S20: 2 | T20: 1 | U20: 22 | W20: 1 | X20: 1 | Y20: 8 | Z20: 1 | AA20: 2 | AB20: 6 | AC20: -4 | AD20: 6 | AE20: =AVERAGE(S20:AD20) -> 4.1818182 | AF20: =_xlfn.STDEV.P(S20:AD20) -> 6.4359527 | AG20: =AF20/AE20 -> 1.5390322 | AH20: =IF(AG20>0.6, "High",IF(AG20>0.3, "Moderate","Stable")) -> High | AI20: =_xlfn.XLOOKUP(R20,Table1[SKU_Code],Table1[Category],"Missing") -> Sweatshirts | AJ20: =SLOPE(Table17[[#This Row],[Jan]:[Dec]], {1,2,3,4,5,6,7,8,9,10,11,12}) -> -0.42923899 | AK20: =IF(Table17[[#This Row],[Slope]]>5,"Growing", IF(Table17[[#This Row],[Slope]]<-5,"Declining","Flat")) -> Flat
B21: PRD-018 | C21: 4 | E21: 11 | H21: 6 | I21: 4 | K21: 2 | L21: 3 | M21: 14 | N21: 2 | O21: 46 | R21: PRD-018 | S21: 4 | U21: 11 | X21: 6 | Y21: 4 | AA21: 2 | AB21: 3 | AC21: 14 | AD21: 2 | AE21: =AVERAGE(S21:AD21) -> 5.75 | AF21: =_xlfn.STDEV.P(S21:AD21) -> 4.145781 | AG21: =AF21/AE21 -> 0.72100539 | AH21: =IF(AG21>0.6, "High",IF(AG21>0.3, "Moderate","Stable")) -> High | AI21: =_xlfn.XLOOKUP(R21,Table1[SKU_Code],Table1[Category],"Missing") -> Shirts | AJ21: =SLOPE(Table17[[#This Row],[Jan]:[Dec]], {1,2,3,4,5,6,7,8,9,10,11,12}) -> -0.11570248 | AK21: =IF(Table17[[#This Row],[Slope]]>5,"Growing", IF(Table17[[#This Row],[Slope]]<-5,"Declining","Flat")) -> Flat
B22: PRD-019 | C22: 1 | E22: 9 | F22: 5 | G22: 4 | H22: 6 | I22: 4 | J22: 1 | K22: 13 | L22: 4 | M22: 2 | N22: 5 | O22: 54 | R22: PRD-019 | S22: 1 | U22: 9 | V22: 5 | W22: 4 | X22: 6 | Y22: 4 | Z22: 1 | AA22: 13 | AB22: 4 | AC22: 2 | AD22: 5 | AE22: =AVERAGE(S22:AD22) -> 4.9090909 | AF22: =_xlfn.STDEV.P(S22:AD22) -> 3.3697733 | AG22: =AF22/AE22 -> 0.6864353 | AH22: =IF(AG22>0.6, "High",IF(AG22>0.3, "Moderate","Stable")) -> High | AI22: =_xlfn.XLOOKUP(R22,Table1[SKU_Code],Table1[Category],"Missing") -> Shirts | AJ22: =SLOPE(Table17[[#This Row],[Jan]:[Dec]], {1,2,3,4,5,6,7,8,9,10,11,12}) -> 0.04887218 | AK22: =IF(Table17[[#This Row],[Slope]]>5,"Growing", IF(Table17[[#This Row],[Slope]]<-5,"Declining","Flat")) -> Flat
B23: PRD-020 | C23: 2 | D23: 8 | E23: 0 | F23: 7 | G23: 4 | H23: 1 | I23: 6 | J23: 2 | K23: 9 | L23: 4 | N23: 5 | O23: 48 | R23: PRD-020 | S23: 2 | T23: 8 | U23: 0 | V23: 7 | W23: 4 | X23: 1 | Y23: 6 | Z23: 2 | AA23: 9 | AB23: 4 | AD23: 5 | AE23: =AVERAGE(S23:AD23) -> 4.3636364 | AF23: =_xlfn.STDEV.P(S23:AD23) -> 2.8049543 | AG23: =AF23/AE23 -> 0.64280203 | AH23: =IF(AG23>0.6, "High",IF(AG23>0.3, "Moderate","Stable")) -> High | AI23: =_xlfn.XLOOKUP(R23,Table1[SKU_Code],Table1[Category],"Missing") -> Shirts | AJ23: =SLOPE(Table17[[#This Row],[Jan]:[Dec]], {1,2,3,4,5,6,7,8,9,10,11,12}) -> 0.15413534 | AK23: =IF(Table17[[#This Row],[Slope]]>5,"Growing", IF(Table17[[#This Row],[Slope]]<-5,"Declining","Flat")) -> Flat
B24: PRD-021 | C24: 14 | D24: 4 | E24: 10 | F24: 7 | G24: 7 | H24: 1 | I24: 4 | J24: 2 | K24: 4 | L24: 3 | M24: 8 | N24: 5 | O24: 69 | R24: PRD-021 | S24: 14 | T24: 4 | U24: 10 | V24: 7 | W24: 7 | X24: 1 | Y24: 4 | Z24: 2 | AA24: 4 | AB24: 3 | AC24: 8 | AD24: 5 | AE24: =AVERAGE(S24:AD24) -> 5.75 | AF24: =_xlfn.STDEV.P(S24:AD24) -> 3.5148495 | AG24: =AF24/AE24 -> 0.61127817 | AH24: =IF(AG24>0.6, "High",IF(AG24>0.3, "Moderate","Stable")) -> High | AI24: =_xlfn.XLOOKUP(R24,Table1[SKU_Code],Table1[Category],"Missing") -> Co-ord Sets | AJ24: =SLOPE(Table17[[#This Row],[Jan]:[Dec]], {1,2,3,4,5,6,7,8,9,10,11,12}) -> -0.48601399 | AK24: =IF(Table17[[#This Row],[Slope]]>5,"Growing", IF(Table17[[#This Row],[Slope]]<-5,"Declining","Flat")) -> Flat
B25: PRD-022 | C25: 2 | E25: 4 | F25: 9 | G25: 2 | H25: 2 | I25: 1 | J25: 4 | K25: 5 | L25: 2 | M25: 15 | N25: 9 | O25: 55 | R25: PRD-022 | S25: 2 | U25: 4 | V25: 9 | W25: 2 | X25: 2 | Y25: 1 | Z25: 4 | AA25: 5 | AB25: 2 | AC25: 15 | AD25: 9 | AE25: =AVERAGE(S25:AD25) -> 5 | AF25: =_xlfn.STDEV.P(S25:AD25) -> 4.1120665 | AG25: =AF25/AE25 -> 0.8224133 | AH25: =IF(AG25>0.6, "High",IF(AG25>0.3, "Moderate","Stable")) -> High | AI25: =_xlfn.XLOOKUP(R25,Table1[SKU_Code],Table1[Category],"Missing") -> Co-ord Sets | AJ25: =SLOPE(Table17[[#This Row],[Jan]:[Dec]], {1,2,3,4,5,6,7,8,9,10,11,12}) -> 0.57067669 | AK25: =IF(Table17[[#This Row],[Slope]]>5,"Growing", IF(Table17[[#This Row],[Slope]]<-5,"Declining","Flat")) -> Flat
B26: PRD-023 | C26: 1 | D26: 1 | E26: 8 | G26: 0 | H26: 4 | I26: 6 | J26: 2 | K26: 4 | L26: 6 | M26: 10 | N26: 5 | O26: 47 | R26: PRD-023 | S26: 1 | T26: 1 | U26: 8 | W26: 0 | X26: 4 | Y26: 6 | Z26: 2 | AA26: 4 | AB26: 6 | AC26: 10 | AD26: 5 | AE26: =AVERAGE(S26:AD26) -> 4.2727273 | AF26: =_xlfn.STDEV.P(S26:AD26) -> 2.9875776 | AG26: =AF26/AE26 -> 0.69922029 | AH26: =IF(AG26>0.6, "High",IF(AG26>0.3, "Moderate","Stable")) -> High | AI26: =_xlfn.XLOOKUP(R26,Table1[SKU_Code],Table1[Category],"Missing") -> Co-ord Sets | AJ26: =SLOPE(Table17[[#This Row],[Jan]:[Dec]], {1,2,3,4,5,6,7,8,9,10,11,12}) -> 0.43190921 | AK26: =IF(Table17[[#This Row],[Slope]]>5,"Growing", IF(Table17[[#This Row],[Slope]]<-5,"Declining","Flat")) -> Flat
B27: PRD-024 | C27: 6 | E27: 9 | G27: 2 | H27: 6 | I27: 4 | K27: 4 | L27: 12 | M27: 17 | N27: 10 | O27: 70 | R27: PRD-024 | S27: 6 | U27: 9 | W27: 2 | X27: 6 | Y27: 4 | AA27: 4 | AB27: 12 | AC27: 17 | AD27: 10 | AE27: =AVERAGE(S27:AD27) -> 7.7777778 | AF27: =_xlfn.STDEV.P(S27:AD27) -> 4.4416658 | AG27: =AF27/AE27 -> 0.57107132 | AH27: =IF(AG27>0.6, "High",IF(AG27>0.3, "Moderate","Stable")) -> Moderate | AI27: =_xlfn.XLOOKUP(R27,Table1[SKU_Code],Table1[Category],"Missing") -> Co-ord Sets | AJ27: =SLOPE(Table17[[#This Row],[Jan]:[Dec]], {1,2,3,4,5,6,7,8,9,10,11,12}) -> 0.65130261 | AK27: =IF(Table17[[#This Row],[Slope]]>5,"Growing", IF(Table17[[#This Row],[Slope]]<-5,"Declining","Flat")) -> Flat
B28: PRD-025 | C28: 5 | D28: 6 | E28: 3 | F28: 3 | G28: 7 | H28: 9 | I28: 3 | J28: 4 | K28: 4 | L28: 4 | M28: 11 | N28: 3 | O28: 62 | R28: PRD-025 | S28: 5 | T28: 6 | U28: 3 | V28: 3 | W28: 7 | X28: 9 | Y28: 3 | Z28: 4 | AA28: 4 | AB28: 4 | AC28: 11 | AD28: 3 | AE28: =AVERAGE(S28:AD28) -> 5.1666667 | AF28: =_xlfn.STDEV.P(S28:AD28) -> 2.5110865 | AG28: =AF28/AE28 -> 0.48601675 | AH28: =IF(AG28>0.6, "High",IF(AG28>0.3, "Moderate","Stable")) -> Moderate | AI28: =_xlfn.XLOOKUP(R28,Table1[SKU_Code],Table1[Category],"Missing") -> Skirts | AJ28: =SLOPE(Table17[[#This Row],[Jan]:[Dec]], {1,2,3,4,5,6,7,8,9,10,11,12}) -> 0.06993007 | AK28: =IF(Table17[[#This Row],[Slope]]>5,"Growing", IF(Table17[[#This Row],[Slope]]<-5,"Declining","Flat")) -> Flat
B29: PRD-026 | C29: 3 | E29: 5 | F29: 1 | G29: 2 | H29: 2 | I29: 5 | J29: 6 | K29: 11 | L29: 3 | M29: 3 | N29: 10 | O29: 51 | R29: PRD-026 | S29: 3 | U29: 5 | V29: 1 | W29: 2 | X29: 2 | Y29: 5 | Z29: 6 | AA29: 11 | AB29: 3 | AC29: 3 | AD29: 10 | AE29: =AVERAGE(S29:AD29) -> 4.6363636 | AF29: =_xlfn.STDEV.P(S29:AD29) -> 3.112226 | AG29: =AF29/AE29 -> 0.67126442 | AH29: =IF(AG29>0.6, "High",IF(AG29>0.3, "Moderate","Stable")) -> High | AI29: =_xlfn.XLOOKUP(R29,Table1[SKU_Code],Table1[Category],"Missing") -> Skirts | AJ29: =SLOPE(Table17[[#This Row],[Jan]:[Dec]], {1,2,3,4,5,6,7,8,9,10,11,12}) -> 0.46842105 | AK29: =IF(Table17[[#This Row],[Slope]]>5,"Growing", IF(Table17[[#This Row],[Slope]]<-5,"Declining","Flat")) -> Flat
B30: PRD-027 | C30: 4 | D30: 3 | E30: 13 | F30: 2 | H30: 7 | I30: 3 | K30: 4 | L30: 4 | M30: 2 | N30: 7 | O30: 49 | R30: PRD-027 | S30: 4 | T30: 3 | U30: 13 | V30: 2 | X30: 7 | Y30: 3 | AA30: 4 | AB30: 4 | AC30: 2 | AD30: 7 | AE30: =AVERAGE(S30:AD30) -> 4.9 | AF30: =_xlfn.STDEV.P(S30:AD30) -> 3.176476 | AG30: =AF30/AE30 -> 0.64826042 | AH30: =IF(AG30>0.6, "High",IF(AG30>0.3, "Moderate","Stable")) -> High | AI30: =_xlfn.XLOOKUP(R30,Table1[SKU_Code],Table1[Category],"Missing") -> Dresses | AJ30: =SLOPE(Table17[[#This Row],[Jan]:[Dec]], {1,2,3,4,5,6,7,8,9,10,11,12}) -> -0.11913357 | AK30: =IF(Table17[[#This Row],[Slope]]>5,"Growing", IF(Table17[[#This Row],[Slope]]<-5,"Declining","Flat")) -> Flat
B31: PRD-028 | C31: 3 | D31: 5 | E31: 9 | F31: 3 | G31: 1 | H31: 1 | I31: 3 | J31: 1 | K31: 7 | L31: 4 | M31: 3 | N31: 7 | O31: 47 | R31: PRD-028 | S31: 3 | T31: 5 | U31: 9 | V31: 3 | W31: 1 | X31: 1 | Y31: 3 | Z31: 1 | AA31: 7 | AB31: 4 | AC31: 3 | AD31: 7 | AE31: =AVERAGE(S31:AD31) -> 3.9166667 | AF31: =_xlfn.STDEV.P(S31:AD31) -> 2.4986107 | AG31: =AF31/AE31 -> 0.63794316 | AH31: =IF(AG31>0.6, "High",IF(AG31>0.3, "Moderate","Stable")) -> High | AI31: =_xlfn.XLOOKUP(R31,Table1[SKU_Code],Table1[Category],"Missing") -> Dresses | AJ31: =SLOPE(Table17[[#This Row],[Jan]:[Dec]], {1,2,3,4,5,6,7,8,9,10,11,12}) -> 0.045454545 | AK31: =IF(Table17[[#This Row],[Slope]]>5,"Growing", IF(Table17[[#This Row],[Slope]]<-5,"Declining","Flat")) -> Flat
B32: PRD-029 | C32: 1 | E32: 13 | F32: 4 | G32: 8 | H32: 2 | I32: 2 | J32: 2 | K32: 5 | L32: 5 | M32: 5 | N32: 12 | O32: 59 | R32: PRD-029 | S32: 1 | U32: 13 | V32: 4 | W32: 8 | X32: 2 | Y32: 2 | Z32: 2 | AA32: 5 | AB32: 5 | AC32: 5 | AD32: 12 | AE32: =AVERAGE(S32:AD32) -> 5.3636364 | AF32: =_xlfn.STDEV.P(S32:AD32) -> 3.867645 | AG32: =AF32/AE32 -> 0.72108635 | AH32: =IF(AG32>0.6, "High",IF(AG32>0.3, "Moderate","Stable")) -> High | AI32: =_xlfn.XLOOKUP(R32,Table1[SKU_Code],Table1[Category],"Missing") -> Dresses | AJ32: =SLOPE(Table17[[#This Row],[Jan]:[Dec]], {1,2,3,4,5,6,7,8,9,10,11,12}) -> 0.20150376 | AK32: =IF(Table17[[#This Row],[Slope]]>5,"Growing", IF(Table17[[#This Row],[Slope]]<-5,"Declining","Flat")) -> Flat
B33: PRD-030 | C33: 1 | E33: 14 | F33: 4 | G33: 5 | H33: 6 | I33: 13 | J33: 3 | K33: 1 | L33: 2 | N33: 6 | O33: 55 | R33: PRD-030 | S33: 1 | U33: 14 | V33: 4 | W33: 5 | X33: 6 | Y33: 13 | Z33: 3 | AA33: 1 | AB33: 2 | AD33: 6 | AE33: =AVERAGE(S33:AD33) -> 5.5 | AF33: =_xlfn.STDEV.P(S33:AD33) -> 4.3646306 | AG33: =AF33/AE33 -> 0.79356919 | AH33: =IF(AG33>0.6, "High",IF(AG33>0.3, "Moderate","Stable")) -> High | AI33: =_xlfn.XLOOKUP(R33,Table1[SKU_Code],Table1[Category],"Missing") -> Dresses | AJ33: =SLOPE(Table17[[#This Row],[Jan]:[Dec]], {1,2,3,4,5,6,7,8,9,10,11,12}) -> -0.2097561 | AK33: =IF(Table17[[#This Row],[Slope]]>5,"Growing", IF(Table17[[#This Row],[Slope]]<-5,"Declining","Flat")) -> Flat
B34: PRD-031 | C34: 12 | D34: 4 | E34: 5 | F34: 7 | H34: 3 | I34: 2 | J34: 4 | K34: 10 | L34: 10 | M34: 9 | N34: 8 | O34: 74 | R34: PRD-031 | S34: 12 | T34: 4 | U34: 5 | V34: 7 | X34: 3 | Y34: 2 | Z34: 4 | AA34: 10 | AB34: 10 | AC34: 9 | AD34: 8 | AE34: =AVERAGE(S34:AD34) -> 6.7272727 | AF34: =_xlfn.STDEV.P(S34:AD34) -> 3.16489 | AH34: Excluded — insufficient data | AI34: =_xlfn.XLOOKUP(R34,Table1[SKU_Code],Table1[Category],"Missing") -> Outerwear | AJ34: =SLOPE(Table17[[#This Row],[Jan]:[Dec]], {1,2,3,4,5,6,7,8,9,10,11,12}) -> 0.14877102 | AK34: =IF(Table17[[#This Row],[Slope]]>5,"Growing", IF(Table17[[#This Row],[Slope]]<-5,"Declining","Flat")) -> Flat
B35: PRD-032 | C35: 4 | D35: 1 | E35: 9 | F35: 5 | G35: 1 | H35: 10 | I35: 8 | J35: -2 | K35: 8 | L35: 2 | M35: 5 | N35: 4 | O35: 55 | R35: PRD-032 | S35: 4 | T35: 1 | U35: 9 | V35: 5 | W35: 1 | X35: 10 | Y35: 8 | Z35: -2 | AA35: 8 | AB35: 2 | AC35: 5 | AD35: 4 | AE35: =AVERAGE(S35:AD35) -> 4.5833333 | AF35: =_xlfn.STDEV.P(S35:AD35) -> 3.5227436 | AG35: =AF35/AE35 -> 0.7685986 | AH35: =IF(AG35>0.6, "High",IF(AG35>0.3, "Moderate","Stable")) -> High | AI35: =_xlfn.XLOOKUP(R35,Table1[SKU_Code],Table1[Category],"Missing") -> Outerwear | AJ35: =SLOPE(Table17[[#This Row],[Jan]:[Dec]], {1,2,3,4,5,6,7,8,9,10,11,12}) -> -0.031468531 | AK35: =IF(Table17[[#This Row],[Slope]]>5,"Growing", IF(Table17[[#This Row],[Slope]]<-5,"Declining","Flat")) -> Flat
B36: PRD-033 | C36: 5 | D36: 2 | E36: 1 | F36: 3 | G36: 3 | H36: 11 | I36: 2 | M36: 8 | N36: 12 | O36: 47 | R36: PRD-033 | S36: 5 | T36: 2 | U36: 1 | V36: 3 | W36: 3 | X36: 11 | Y36: 2 | AC36: 8 | AD36: 12 | AE36: =AVERAGE(S36:AD36) -> 5.2222222 | AF36: =_xlfn.STDEV.P(S36:AD36) -> 3.8809443 | AG36: =AF36/AE36 -> 0.74315954 | AH36: =IF(AG36>0.6, "High",IF(AG36>0.3, "Moderate","Stable")) -> High | AI36: =_xlfn.XLOOKUP(R36,Table1[SKU_Code],Table1[Category],"Missing") -> Knitwear | AJ36: =SLOPE(Table17[[#This Row],[Jan]:[Dec]], {1,2,3,4,5,6,7,8,9,10,11,12}) -> 0.72988506 | AK36: =IF(Table17[[#This Row],[Slope]]>5,"Growing", IF(Table17[[#This Row],[Slope]]<-5,"Declining","Flat")) -> Flat
B37: PRD-034 | D37: 2 | E37: 9 | F37: 9 | G37: 3 | I37: 3 | J37: 2 | K37: 3 | L37: 1 | M37: 2 | N37: 16 | O37: 50 | R37: PRD-034 | T37: 2 | U37: 9 | V37: 9 | W37: 3 | Y37: 3 | Z37: 2 | AA37: 3 | AB37: 1 | AC37: 2 | AD37: 16 | AE37: =AVERAGE(S37:AD37) -> 5 | AF37: =_xlfn.STDEV.P(S37:AD37) -> 4.5607017 | AG37: =AF37/AE37 -> 0.91214034 | AH37: =IF(AG37>0.6, "High",IF(AG37>0.3, "Moderate","Stable")) -> High | AI37: =_xlfn.XLOOKUP(R37,Table1[SKU_Code],Table1[Category],"Missing") -> Pyjamas | AJ37: =SLOPE(Table17[[#This Row],[Jan]:[Dec]], {1,2,3,4,5,6,7,8,9,10,11,12}) -> 0.13774105 | AK37: =IF(Table17[[#This Row],[Slope]]>5,"Growing", IF(Table17[[#This Row],[Slope]]<-5,"Declining","Flat")) -> Flat
B38: PRD-035 | C38: 2 | D38: 7 | E38: 16 | F38: 3 | G38: 2 | H38: 5 | I38: 7 | J38: 1 | K38: 6 | L38: 9 | M38: 2 | N38: 4 | O38: 64 | R38: PRD-035 | S38: 2 | T38: 7 | U38: 16 | V38: 3 | W38: 2 | X38: 5 | Y38: 7 | Z38: 1 | AA38: 6 | AB38: 9 | AC38: 2 | AD38: 4 | AE38: =AVERAGE(S38:AD38) -> 5.3333333 | AF38: =_xlfn.STDEV.P(S38:AD38) -> 4.0069384 | AG38: =AF38/AE38 -> 0.75130096 | AH38: =IF(AG38>0.6, "High",IF(AG38>0.3, "Moderate","Stable")) -> High | AI38: =_xlfn.XLOOKUP(R38,Table1[SKU_Code],Table1[Category],"Missing") -> Basics | AJ38: =SLOPE(Table17[[#This Row],[Jan]:[Dec]], {1,2,3,4,5,6,7,8,9,10,11,12}) -> -0.2027972 | AK38: =IF(Table17[[#This Row],[Slope]]>5,"Growing", IF(Table17[[#This Row],[Slope]]<-5,"Declining","Flat")) -> Flat
B39: PRD-036 | C39: 6 | E39: 8 | F39: 5 | G39: 1 | H39: 1 | I39: 3 | J39: 5 | K39: 10 | L39: 5 | M39: 5 | N39: 9 | O39: 58 | R39: PRD-036 | S39: 6 | U39: 8 | V39: 5 | W39: 1 | X39: 1 | Y39: 3 | Z39: 5 | AA39: 10 | AB39: 5 | AC39: 5 | AD39: 9 | AE39: =AVERAGE(S39:AD39) -> 5.2727273 | AF39: =_xlfn.STDEV.P(S39:AD39) -> 2.7990553 | AG39: =AF39/AE39 -> 0.53085532 | AH39: =IF(AG39>0.6, "High",IF(AG39>0.3, "Moderate","Stable")) -> Moderate | AI39: =_xlfn.XLOOKUP(R39,Table1[SKU_Code],Table1[Category],"Missing") -> Basics | AJ39: =SLOPE(Table17[[#This Row],[Jan]:[Dec]], {1,2,3,4,5,6,7,8,9,10,11,12}) -> 0.20075188 | AK39: =IF(Table17[[#This Row],[Slope]]>5,"Growing", IF(Table17[[#This Row],[Slope]]<-5,"Declining","Flat")) -> Flat
B40: PRD-037 | C40: 1 | E40: 8 | F40: 7 | G40: 1 | H40: 11 | I40: 1 | J40: 14 | K40: 3 | L40: 5 | M40: 10 | N40: 10 | O40: 71 | R40: PRD-037 | S40: 1 | U40: 8 | V40: 7 | W40: 1 | X40: 11 | Y40: 1 | Z40: 14 | AA40: 3 | AB40: 5 | AC40: 10 | AD40: 10 | AE40: =AVERAGE(S40:AD40) -> 6.4545455 | AF40: =_xlfn.STDEV.P(S40:AD40) -> 4.356054 | AG40: =AF40/AE40 -> 0.67488161 | AH40: =IF(AG40>0.6, "High",IF(AG40>0.3, "Moderate","Stable")) -> High | AI40: =_xlfn.XLOOKUP(R40,Table1[SKU_Code],Table1[Category],"Missing") -> Basics | AJ40: =SLOPE(Table17[[#This Row],[Jan]:[Dec]], {1,2,3,4,5,6,7,8,9,10,11,12}) -> 0.49172932 | AK40: =IF(Table17[[#This Row],[Slope]]>5,"Growing", IF(Table17[[#This Row],[Slope]]<-5,"Declining","Flat")) -> Flat
B41: PRD-038 | C41: -2 | D41: 3 | E41: 6 | F41: 3 | H41: 10 | I41: 7 | J41: 3 | K41: 2 | L41: 2 | M41: 4 | N41: 3 | O41: 41 | R41: PRD-038 | S41: -2 | T41: 3 | U41: 6 | V41: 3 | X41: 10 | Y41: 7 | Z41: 3 | AA41: 2 | AB41: 2 | AC41: 4 | AD41: 3 | AE41: =AVERAGE(S41:AD41) -> 3.7272727 | AF41: =_xlfn.STDEV.P(S41:AD41) -> 2.956992 | AG41: =AF41/AE41 -> 0.79333932 | AH41: =IF(AG41>0.6, "High",IF(AG41>0.3, "Moderate","Stable")) -> High | AI41: =_xlfn.XLOOKUP(R41,Table1[SKU_Code],Table1[Category],"Missing") -> Dresses | AJ41: =SLOPE(Table17[[#This Row],[Jan]:[Dec]], {1,2,3,4,5,6,7,8,9,10,11,12}) -> 0.091849935 | AK41: =IF(Table17[[#This Row],[Slope]]>5,"Growing", IF(Table17[[#This Row],[Slope]]<-5,"Declining","Flat")) -> Flat
...

Sheet Inventory Analysis
A1: SKU_Code | B1: Product_Name | C1: Category | D1: Avg_Monthly_Demand | E1: Std Dev | F1: Avg_Daily_Demand | G1: Lead_Time_Days | H1: Safety_Stock | I1: ROP | J1: Units_On_Hand | K1: Reorder_Lvl | L1: Days_of_Supply | M1: Stock_Status
A2: PRD-001 | B2: =_xlfn.XLOOKUP(A2,Table1[SKU_Code],Table1[Product_Name],"Missing") -> Beige Co-ord Set | C2: =_xlfn.XLOOKUP(A2,Table1[SKU_Code],Table1[Category],"Missing") -> Co-ord Sets | D2: =_xlfn.XLOOKUP(A2,Table17[Row Labels],Table17[Average Monthly Qty],"Missing") -> 3.7272727 | E2: =_xlfn.XLOOKUP(A2,Table17[Row Labels],Table17[Std Dev],"Missing") -> 2.489648 | F2: =IF(D2="Missing","Missing",ROUND(D2/30,2)) -> 0.12 | G2: 14 | H2: =ROUND(1.65*E2*SQRT(G2/30),0) -> 3 | I2: =ROUND((F2*G2)+H2,0) -> 5 | J2: =_xlfn.LET(_xlpm.x,_xlfn.XLOOKUP(A2,Table2[SKU_Code],Table2[Units_On_Hand],""),IF(_xlpm.x="","Missing",_xlpm.x)) -> 3 | K2: =_xlfn.LET(_xlpm.x,_xlfn.XLOOKUP(A2,Table2[SKU_Code],Table2[Reorder_Lvl],""),IF(_xlpm.x="","Missing",_xlpm.x)) -> 8 | L2: =IF(OR(J2="Missing",F2=0),"Missing",ROUND(J2/F2,0)) -> 25 | M2: =IF(J2="Missing","Missing",IF(J2<I2,"Reorder Now","OK")) -> Reorder Now
A3: PRD-002 | B3: =_xlfn.XLOOKUP(A3,Table1[SKU_Code],Table1[Product_Name],"Missing") -> Beige Co-ord Set | C3: =_xlfn.XLOOKUP(A3,Table1[SKU_Code],Table1[Category],"Missing") -> Co-ord Sets | D3: =_xlfn.XLOOKUP(A3,Table17[Row Labels],Table17[Average Monthly Qty],"Missing") -> 5.75 | E3: =_xlfn.XLOOKUP(A3,Table17[Row Labels],Table17[Std Dev],"Missing") -> 4.1857895 | F3: =IF(D3="Missing","Missing",ROUND(D3/30,2)) -> 0.19 | G3: 14 | H3: =ROUND(1.65*E3*SQRT(G3/30),0) -> 5 | I3: =ROUND((F3*G3)+H3,0) -> 8 | J3: =_xlfn.LET(_xlpm.x,_xlfn.XLOOKUP(A3,Table2[SKU_Code],Table2[Units_On_Hand],""),IF(_xlpm.x="","Missing",_xlpm.x)) -> 23 | K3: =_xlfn.LET(_xlpm.x,_xlfn.XLOOKUP(A3,Table2[SKU_Code],Table2[Reorder_Lvl],""),IF(_xlpm.x="","Missing",_xlpm.x)) -> 5 | L3: =IF(OR(J3="Missing",F3=0),"Missing",ROUND(J3/F3,0)) -> 121 | M3: =IF(J3="Missing","Missing",IF(J3<I3,"Reorder Now","OK")) -> OK
A4: PRD-003 | B4: =_xlfn.XLOOKUP(A4,Table1[SKU_Code],Table1[Product_Name],"Missing") -> Beige Co-ord Set | C4: =_xlfn.XLOOKUP(A4,Table1[SKU_Code],Table1[Category],"Missing") -> Co-ord Sets | D4: =_xlfn.XLOOKUP(A4,Table17[Row Labels],Table17[Average Monthly Qty],"Missing") -> 5.6363636 | E4: =_xlfn.XLOOKUP(A4,Table17[Row Labels],Table17[Std Dev],"Missing") -> 3.7239453 | F4: =IF(D4="Missing","Missing",ROUND(D4/30,2)) -> 0.19 | G4: 14 | H4: =ROUND(1.65*E4*SQRT(G4/30),0) -> 4 | I4: =ROUND((F4*G4)+H4,0) -> 7 | J4: =_xlfn.LET(_xlpm.x,_xlfn.XLOOKUP(A4,Table2[SKU_Code],Table2[Units_On_Hand],""),IF(_xlpm.x="","Missing",_xlpm.x)) -> 4 | K4: =_xlfn.LET(_xlpm.x,_xlfn.XLOOKUP(A4,Table2[SKU_Code],Table2[Reorder_Lvl],""),IF(_xlpm.x="","Missing",_xlpm.x)) -> 10 | L4: =IF(OR(J4="Missing",F4=0),"Missing",ROUND(J4/F4,0)) -> 21 | M4: =IF(J4="Missing","Missing",IF(J4<I4,"Reorder Now","OK")) -> Reorder Now
A5: PRD-004 | B5: =_xlfn.XLOOKUP(A5,Table1[SKU_Code],Table1[Product_Name],"Missing") -> Pink Sweatshirt | C5: =_xlfn.XLOOKUP(A5,Table1[SKU_Code],Table1[Category],"Missing") -> Sweatshirts | D5: =_xlfn.XLOOKUP(A5,Table17[Row Labels],Table17[Average Monthly Qty],"Missing") -> 5.7272727 | E5: =_xlfn.XLOOKUP(A5,Table17[Row Labels],Table17[Std Dev],"Missing") -> 3.2218264 | F5: =IF(D5="Missing","Missing",ROUND(D5/30,2)) -> 0.19 | G5: 14 | H5: =ROUND(1.65*E5*SQRT(G5/30),0) -> 4 | I5: =ROUND((F5*G5)+H5,0) -> 7 | J5: =_xlfn.LET(_xlpm.x,_xlfn.XLOOKUP(A5,Table2[SKU_Code],Table2[Units_On_Hand],""),IF(_xlpm.x="","Missing",_xlpm.x)) -> 13 | K5: =_xlfn.LET(_xlpm.x,_xlfn.XLOOKUP(A5,Table2[SKU_Code],Table2[Reorder_Lvl],""),IF(_xlpm.x="","Missing",_xlpm.x)) -> 8 | L5: =IF(OR(J5="Missing",F5=0),"Missing",ROUND(J5/F5,0)) -> 68 | M5: =IF(J5="Missing","Missing",IF(J5<I5,"Reorder Now","OK")) -> OK
A6: PRD-005 | B6: =_xlfn.XLOOKUP(A6,Table1[SKU_Code],Table1[Product_Name],"Missing") -> Pink Sweatshirt | C6: =_xlfn.XLOOKUP(A6,Table1[SKU_Code],Table1[Category],"Missing") -> Sweatshirts | D6: =_xlfn.XLOOKUP(A6,Table17[Row Labels],Table17[Average Monthly Qty],"Missing") -> 6.8 | E6: =_xlfn.XLOOKUP(A6,Table17[Row Labels],Table17[Std Dev],"Missing") -> 4.1665333 | F6: =IF(D6="Missing","Missing",ROUND(D6/30,2)) -> 0.23 | G6: 14 | H6: =ROUND(1.65*E6*SQRT(G6/30),0) -> 5 | I6: =ROUND((F6*G6)+H6,0) -> 8 | J6: =_xlfn.LET(_xlpm.x,_xlfn.XLOOKUP(A6,Table2[SKU_Code],Table2[Units_On_Hand],""),IF(_xlpm.x="","Missing",_xlpm.x)) -> 22 | K6: =_xlfn.LET(_xlpm.x,_xlfn.XLOOKUP(A6,Table2[SKU_Code],Table2[Reorder_Lvl],""),IF(_xlpm.x="","Missing",_xlpm.x)) -> 11 | L6: =IF(OR(J6="Missing",F6=0),"Missing",ROUND(J6/F6,0)) -> 96 | M6: =IF(J6="Missing","Missing",IF(J6<I6,"Reorder Now","OK")) -> OK
A7: PRD-006 | B7: =_xlfn.XLOOKUP(A7,Table1[SKU_Code],Table1[Product_Name],"Missing") -> Pink Sweatshirt | C7: =_xlfn.XLOOKUP(A7,Table1[SKU_Code],Table1[Category],"Missing") -> Sweatshirts | D7: =_xlfn.XLOOKUP(A7,Table17[Row Labels],Table17[Average Monthly Qty],"Missing") -> 4.9166667 | E7: =_xlfn.XLOOKUP(A7,Table17[Row Labels],Table17[Std Dev],"Missing") -> 3.8613109 | F7: =IF(D7="Missing","Missing",ROUND(D7/30,2)) -> 0.16 | G7: 14 | H7: =ROUND(1.65*E7*SQRT(G7/30),0) -> 4 | I7: =ROUND((F7*G7)+H7,0) -> 6 | J7: =_xlfn.LET(_xlpm.x,_xlfn.XLOOKUP(A7,Table2[SKU_Code],Table2[Units_On_Hand],""),IF(_xlpm.x="","Missing",_xlpm.x)) -> 40 | K7: =_xlfn.LET(_xlpm.x,_xlfn.XLOOKUP(A7,Table2[SKU_Code],Table2[Reorder_Lvl],""),IF(_xlpm.x="","Missing",_xlpm.x)) -> 10 | L7: =IF(OR(J7="Missing",F7=0),"Missing",ROUND(J7/F7,0)) -> 250 | M7: =IF(J7="Missing","Missing",IF(J7<I7,"Reorder Now","OK")) -> OK
A8: PRD-007 | B8: =_xlfn.XLOOKUP(A8,Table1[SKU_Code],Table1[Product_Name],"Missing") -> Olive Sweatshirt | C8: =_xlfn.XLOOKUP(A8,Table1[SKU_Code],Table1[Category],"Missing") -> Sweatshirts | D8: =_xlfn.XLOOKUP(A8,Table17[Row Labels],Table17[Average Monthly Qty],"Missing") -> 5.2727273 | E8: =_xlfn.XLOOKUP(A8,Table17[Row Labels],Table17[Std Dev],"Missing") -> 3.1069105 | F8: =IF(D8="Missing","Missing",ROUND(D8/30,2)) -> 0.18 | G8: 14 | H8: =ROUND(1.65*E8*SQRT(G8/30),0) -> 4 | I8: =ROUND((F8*G8)+H8,0) -> 7 | J8: =_xlfn.LET(_xlpm.x,_xlfn.XLOOKUP(A8,Table2[SKU_Code],Table2[Units_On_Hand],""),IF(_xlpm.x="","Missing",_xlpm.x)) -> 9 | K8: =_xlfn.LET(_xlpm.x,_xlfn.XLOOKUP(A8,Table2[SKU_Code],Table2[Reorder_Lvl],""),IF(_xlpm.x="","Missing",_xlpm.x)) -> 11 | L8: =IF(OR(J8="Missing",F8=0),"Missing",ROUND(J8/F8,0)) -> 50 | M8: =IF(J8="Missing","Missing",IF(J8<I8,"Reorder Now","OK")) -> OK
A9: PRD-008 | B9: =_xlfn.XLOOKUP(A9,Table1[SKU_Code],Table1[Product_Name],"Missing") -> Olive Sweatshirt | C9: =_xlfn.XLOOKUP(A9,Table1[SKU_Code],Table1[Category],"Missing") -> Sweatshirts | D9: =_xlfn.XLOOKUP(A9,Table17[Row Labels],Table17[Average Monthly Qty],"Missing") -> 6.7272727 | E9: =_xlfn.XLOOKUP(A9,Table17[Row Labels],Table17[Std Dev],"Missing") -> 4.8820806 | F9: =IF(D9="Missing","Missing",ROUND(D9/30,2)) -> 0.22 | G9: 14 | H9: =ROUND(1.65*E9*SQRT(G9/30),0) -> 6 | I9: =ROUND((F9*G9)+H9,0) -> 9 | J9: =_xlfn.LET(_xlpm.x,_xlfn.XLOOKUP(A9,Table2[SKU_Code],Table2[Units_On_Hand],""),IF(_xlpm.x="","Missing",_xlpm.x)) -> Missing | K9: =_xlfn.LET(_xlpm.x,_xlfn.XLOOKUP(A9,Table2[SKU_Code],Table2[Reorder_Lvl],""),IF(_xlpm.x="","Missing",_xlpm.x)) -> 10 | L9: =IF(OR(J9="Missing",F9=0),"Missing",ROUND(J9/F9,0)) -> Missing | M9: =IF(J9="Missing","Missing",IF(J9<I9,"Reorder Now","OK")) -> Missing
A10: PRD-009 | B10: =_xlfn.XLOOKUP(A10,Table1[SKU_Code],Table1[Product_Name],"Missing") -> Red Sweatshirt | C10: =_xlfn.XLOOKUP(A10,Table1[SKU_Code],Table1[Category],"Missing") -> Sweatshirts | D10: =_xlfn.XLOOKUP(A10,Table17[Row Labels],Table17[Average Monthly Qty],"Missing") -> 6.4545455 | E10: =_xlfn.XLOOKUP(A10,Table17[Row Labels],Table17[Std Dev],"Missing") -> 3.4208887 | F10: =IF(D10="Missing","Missing",ROUND(D10/30,2)) -> 0.22 | G10: 14 | H10: =ROUND(1.65*E10*SQRT(G10/30),0) -> 4 | I10: =ROUND((F10*G10)+H10,0) -> 7 | J10: =_xlfn.LET(_xlpm.x,_xlfn.XLOOKUP(A10,Table2[SKU_Code],Table2[Units_On_Hand],""),IF(_xlpm.x="","Missing",_xlpm.x)) -> 2 | K10: =_xlfn.LET(_xlpm.x,_xlfn.XLOOKUP(A10,Table2[SKU_Code],Table2[Reorder_Lvl],""),IF(_xlpm.x="","Missing",_xlpm.x)) -> 7 | L10: =IF(OR(J10="Missing",F10=0),"Missing",ROUND(J10/F10,0)) -> 9 | M10: =IF(J10="Missing","Missing",IF(J10<I10,"Reorder Now","OK")) -> Reorder Now
A11: PRD-010 | B11: =_xlfn.XLOOKUP(A11,Table1[SKU_Code],Table1[Product_Name],"Missing") -> Blue Sweatshirt | C11: =_xlfn.XLOOKUP(A11,Table1[SKU_Code],Table1[Category],"Missing") -> Sweatshirts | D11: =_xlfn.XLOOKUP(A11,Table17[Row Labels],Table17[Average Monthly Qty],"Missing") -> 3.6363636 | E11: =_xlfn.XLOOKUP(A11,Table17[Row Labels],Table17[Std Dev],"Missing") -> 2.3845231 | F11: =IF(D11="Missing","Missing",ROUND(D11/30,2)) -> 0.12 | G11: 14 | H11: =ROUND(1.65*E11*SQRT(G11/30),0) -> 3 | I11: =ROUND((F11*G11)+H11,0) -> 5 | J11: =_xlfn.LET(_xlpm.x,_xlfn.XLOOKUP(A11,Table2[SKU_Code],Table2[Units_On_Hand],""),IF(_xlpm.x="","Missing",_xlpm.x)) -> 10 | K11: =_xlfn.LET(_xlpm.x,_xlfn.XLOOKUP(A11,Table2[SKU_Code],Table2[Reorder_Lvl],""),IF(_xlpm.x="","Missing",_xlpm.x)) -> 8 | L11: =IF(OR(J11="Missing",F11=0),"Missing",ROUND(J11/F11,0)) -> 83 | M11: =IF(J11="Missing","Missing",IF(J11<I11,"Reorder Now","OK")) -> OK
A12: PRD-011 | B12: =_xlfn.XLOOKUP(A12,Table1[SKU_Code],Table1[Product_Name],"Missing") -> Burgundy Knit Dress | C12: =_xlfn.XLOOKUP(A12,Table1[SKU_Code],Table1[Category],"Missing") -> Knit Dresses | D12: =_xlfn.XLOOKUP(A12,Table17[Row Labels],Table17[Average Monthly Qty],"Missing") -> 3.8 | E12: =_xlfn.XLOOKUP(A12,Table17[Row Labels],Table17[Std Dev],"Missing") -> 3.4292856 | F12: =IF(D12="Missing","Missing",ROUND(D12/30,2)) -> 0.13 | G12: 14 | H12: =ROUND(1.65*E12*SQRT(G12/30),0) -> 4 | I12: =ROUND((F12*G12)+H12,0) -> 6 | J12: =_xlfn.LET(_xlpm.x,_xlfn.XLOOKUP(A12,Table2[SKU_Code],Table2[Units_On_Hand],""),IF(_xlpm.x="","Missing",_xlpm.x)) -> 35 | K12: =_xlfn.LET(_xlpm.x,_xlfn.XLOOKUP(A12,Table2[SKU_Code],Table2[Reorder_Lvl],""),IF(_xlpm.x="","Missing",_xlpm.x)) -> 16 | L12: =IF(OR(J12="Missing",F12=0),"Missing",ROUND(J12/F12,0)) -> 269 | M12: =IF(J12="Missing","Missing",IF(J12<I12,"Reorder Now","OK")) -> OK
A13: PRD-012 | B13: =_xlfn.XLOOKUP(A13,Table1[SKU_Code],Table1[Product_Name],"Missing") -> Burgundy Knit Dress | C13: =_xlfn.XLOOKUP(A13,Table1[SKU_Code],Table1[Category],"Missing") -> Knit Dresses | D13: =_xlfn.XLOOKUP(A13,Table17[Row Labels],Table17[Average Monthly Qty],"Missing") -> 4.2 | E13: =_xlfn.XLOOKUP(A13,Table17[Row Labels],Table17[Std Dev],"Missing") -> 3.4583233 | F13: =IF(D13="Missing","Missing",ROUND(D13/30,2)) -> 0.14 | G13: 14 | H13: =ROUND(1.65*E13*SQRT(G13/30),0) -> 4 | I13: =ROUND((F13*G13)+H13,0) -> 6 | J13: =_xlfn.LET(_xlpm.x,_xlfn.XLOOKUP(A13,Table2[SKU_Code],Table2[Units_On_Hand],""),IF(_xlpm.x="","Missing",_xlpm.x)) -> 16 | K13: =_xlfn.LET(_xlpm.x,_xlfn.XLOOKUP(A13,Table2[SKU_Code],Table2[Reorder_Lvl],""),IF(_xlpm.x="","Missing",_xlpm.x)) -> 13 | L13: =IF(OR(J13="Missing",F13=0),"Missing",ROUND(J13/F13,0)) -> 114 | M13: =IF(J13="Missing","Missing",IF(J13<I13,"Reorder Now","OK")) -> OK
... A41: PRD-040 | B41: =_xlfn.XLOOKUP(A41,Table1[SKU_Code],Table1[Product_Name],"Missing") -> Navy Wide Leg Pants | C41: =_xlfn.XLOOKUP(A41,Table1[SKU_Code],Table1[Category],"Missing") -> Bottoms | D41: =_xlfn.XLOOKUP(A41,Table17[Row Labels],Table17[Average Monthly Qty],"Missing") -> 4.2727273 | E41: =_xlfn.XLOOKUP(A41,Table17[Row Labels],Table17[Std Dev],"Missing") -> 2.5968831 | F41: =IF(D41="Missing","Missing",ROUND(D41/30,2)) -> 0.14 | G41: 14 | H41: =ROUND(1.65*E41*SQRT(G41/30),0) -> 3 | I41: =ROUND((F41*G41)+H41,0) -> 5 | J41: =_xlfn.LET(_xlpm.x,_xlfn.XLOOKUP(A41,Table2[SKU_Code],Table2[Units_On_Hand],""),IF(_xlpm.x="","Missing",_xlpm.x)) -> 30 | K41: =_xlfn.LET(_xlpm.x,_xlfn.XLOOKUP(A41,Table2[SKU_Code],Table2[Reorder_Lvl],""),IF(_xlpm.x="","Missing",_xlpm.x)) -> 20 | L41: =IF(OR(J41="Missing",F41=0),"Missing",ROUND(J41/F41,0)) -> 214 | M41: =IF(J41="Missing","Missing",IF(J41<I41,"Reorder Now","OK")) -> OK

Sheet Financial Analysis
A1: SKU_Code | B1: Product_Name | C1: Units_Received | D1: Units_Sold | E1: Sell_Through_Rate | F1: Cost_Price | G1: Selling_Price | H1: Gross_Margin_Pct | I1: Total_Revenue | J1: Revenue_Rank | K1: Cumulative_Revenue_Pct | L1: ABC_Class | M1: Gross_Margin_Dollar | N1: Inventory_Investment | O1: GMROI | P1: GMROI_Class
A2: PRD-001 | B2: Beige Co-ord Set | C2: =IFERROR(_xlfn.XLOOKUP(A2,Table2[SKU_Code],Table2[Received_Qty]),"Missing") -> 82 | D2: =IFERROR(SUMIF(Table4[SKU_Code], A2, Table4[Qty]), "Missing") -> 41 | E2: =IFERROR(D2/C2,"Missing") -> 0.5 | F2: =IFERROR(_xlfn.XLOOKUP(A2, Table1[SKU_Code], Table1[Cost_IRR]), "Missing") -> 185000 | G2: =IFERROR(_xlfn.XLOOKUP(A2,Table1[SKU_Code],Table1[RRP_IRR]),"Missing") -> 420000 | H2: =IFERROR((G2-F2)/G2, "Missing") -> 0.55952381 | I2: =SUMIF(Table4[SKU_Code],'Financial Analysis'!A2,Table4[Revenue]) -> 16590000 | J2: =_xlfn.RANK.EQ(I2,$I$2:$I$41,0) -> 12 | K2: =SUMIF($J$2:$J$41,"<="&J2,$I$2:$I$41)/SUM($I$2:$I$41) -> 0.47056008 | L2: =IF(K2<=0.7,"A",IF(K2<=0.9,"B","C")) -> A | M2: =I2-(D2*F2) -> 9005000 | N2: =C2*F2 -> 15170000 | O2: =IFERROR(ROUND(M2/N2,2),"Missing") -> 0.59 | P2: =IF(O2>=2,"A",IF(O2>=1,"B","C")) -> C
A3: PRD-002 | B3: Beige Co-ord Set | C3: =IFERROR(_xlfn.XLOOKUP(A3,Table2[SKU_Code],Table2[Received_Qty]),"Missing") -> 134 | D3: =IFERROR(SUMIF(Table4[SKU_Code], A3, Table4[Qty]), "Missing") -> 69 | E3: =IFERROR(D3/C3,"Missing") -> 0.51492537 | F3: =IFERROR(_xlfn.XLOOKUP(A3, Table1[SKU_Code], Table1[Cost_IRR]), "Missing") -> 185000 | G3: =IFERROR(_xlfn.XLOOKUP(A3,Table1[SKU_Code],Table1[RRP_IRR]),"Missing") -> 420000 | H3: =IFERROR((G3-F3)/G3, "Missing") -> 0.55952381 | I3: =SUMIF(Table4[SKU_Code],'Financial Analysis'!A3,Table4[Revenue]) -> 28098000 | J3: =_xlfn.RANK.EQ(I3,$I$2:$I$41,0) -> 4 | K3: =SUMIF($J$2:$J$41,"<="&J3,$I$2:$I$41)/SUM($I$2:$I$41) -> 0.19482561 | L3: =IF(K3<=0.7,"A",IF(K3<=0.9,"B","C")) -> A | M3: =I3-(D3*F3) -> 15333000 | N3: =C3*F3 -> 24790000 | O3: =IFERROR(ROUND(M3/N3,2),"Missing") -> 0.62 | P3: =IF(O3>=2,"A",IF(O3>=1,"B","C")) -> C
A4: PRD-003 | B4: Beige Co-ord Set | C4: =IFERROR(_xlfn.XLOOKUP(A4,Table2[SKU_Code],Table2[Received_Qty]),"Missing") -> 33 | D4: =IFERROR(SUMIF(Table4[SKU_Code], A4, Table4[Qty]), "Missing") -> 62 | E4: =IFERROR(D4/C4,"Missing") -> 1.8787879 | F4: =IFERROR(_xlfn.XLOOKUP(A4, Table1[SKU_Code], Table1[Cost_IRR]), "Missing") -> 185000 | G4: =IFERROR(_xlfn.XLOOKUP(A4,Table1[SKU_Code],Table1[RRP_IRR]),"Missing") -> 420000 | H4: =IFERROR((G4-F4)/G4, "Missing") -> 0.55952381 | I4: =SUMIF(Table4[SKU_Code],'Financial Analysis'!A4,Table4[Revenue]) -> 24990000 | J4: =_xlfn.RANK.EQ(I4,$I$2:$I$41,0) -> 5 | K4: =SUMIF($J$2:$J$41,"<="&J4,$I$2:$I$41)/SUM($I$2:$I$41) -> 0.23691656 | L4: =IF(K4<=0.7,"A",IF(K4<=0.9,"B","C")) -> A | M4: =I4-(D4*F4) -> 13520000 | N4: =C4*F4 -> 6105000 | O4: =IFERROR(ROUND(M4/N4,2),"Missing") -> 2.21 | P4: =IF(O4>=2,"A",IF(O4>=1,"B","C")) -> A
A5: PRD-004 | B5: Pink Sweatshirt | C5: =IFERROR(_xlfn.XLOOKUP(A5,Table2[SKU_Code],Table2[Received_Qty]),"Missing") -> 39 | D5: =IFERROR(SUMIF(Table4[SKU_Code], A5, Table4[Qty]), "Missing") -> 63 | E5: =IFERROR(D5/C5,"Missing") -> 1.6153846 | F5: =IFERROR(_xlfn.XLOOKUP(A5, Table1[SKU_Code], Table1[Cost_IRR]), "Missing") -> 95000 | G5: =IFERROR(_xlfn.XLOOKUP(A5,Table1[SKU_Code],Table1[RRP_IRR]),"Missing") -> 220000 | H5: =IFERROR((G5-F5)/G5, "Missing") -> 0.56818182 | I5: =SUMIF(Table4[SKU_Code],'Financial Analysis'!A5,Table4[Revenue]) -> 13585000 | J5: =_xlfn.RANK.EQ(I5,$I$2:$I$41,0) -> 19 | K5: =SUMIF($J$2:$J$41,"<="&J5,$I$2:$I$41)/SUM($I$2:$I$41) -> 0.64268285 | L5: =IF(K5<=0.7,"A",IF(K5<=0.9,"B","C")) -> A | M5: =I5-(D5*F5) -> 7600000 | N5: =C5*F5 -> 3705000 | O5: =IFERROR(ROUND(M5/N5,2),"Missing") -> 2.05 | P5: =IF(O5>=2,"A",IF(O5>=1,"B","C")) -> A | S5: Revenue ABC | T5: GMROI Class
A6: PRD-005 | B6: Pink Sweatshirt | C6: =IFERROR(_xlfn.XLOOKUP(A6,Table2[SKU_Code],Table2[Received_Qty]),"Missing") -> 51 | D6: =IFERROR(SUMIF(Table4[SKU_Code], A6, Table4[Qty]), "Missing") -> 68 | E6: =IFERROR(D6/C6,"Missing") -> 1.3333333 | F6: =IFERROR(_xlfn.XLOOKUP(A6, Table1[SKU_Code], Table1[Cost_IRR]), "Missing") -> 95000 | G6: =IFERROR(_xlfn.XLOOKUP(A6,Table1[SKU_Code],Table1[RRP_IRR]),"Missing") -> 220000 | H6: =IFERROR((G6-F6)/G6, "Missing") -> 0.56818182 | I6: =SUMIF(Table4[SKU_Code],'Financial Analysis'!A6,Table4[Revenue]) -> 14256000 | J6: =_xlfn.RANK.EQ(I6,$I$2:$I$41,0) -> 16 | K6: =SUMIF($J$2:$J$41,"<="&J6,$I$2:$I$41)/SUM($I$2:$I$41) -> 0.57271865 | L6: =IF(K6<=0.7,"A",IF(K6<=0.9,"B","C")) -> A | M6: =I6-(D6*F6) -> 7796000 | N6: =C6*F6 -> 4845000 | O6: =IFERROR(ROUND(M6/N6,2),"Missing") -> 1.61 | P6: =IF(O6>=2,"A",IF(O6>=1,"B","C")) -> B | R6: Class A | S6: 20 | T6: 5
A7: PRD-006 | B7: Pink Sweatshirt | C7: =IFERROR(_xlfn.XLOOKUP(A7,Table2[SKU_Code],Table2[Received_Qty]),"Missing") -> 146 | D7: =IFERROR(SUMIF(Table4[SKU_Code], A7, Table4[Qty]), "Missing") -> 59 | E7: =IFERROR(D7/C7,"Missing") -> 0.40410959 | F7: =IFERROR(_xlfn.XLOOKUP(A7, Table1[SKU_Code], Table1[Cost_IRR]), "Missing") -> 95000 | G7: =IFERROR(_xlfn.XLOOKUP(A7,Table1[SKU_Code],Table1[RRP_IRR]),"Missing") -> 220000 | H7: =IFERROR((G7-F7)/G7, "Missing") -> 0.56818182 | I7: =SUMIF(Table4[SKU_Code],'Financial Analysis'!A7,Table4[Revenue]) -> 12672000 | J7: =_xlfn.RANK.EQ(I7,$I$2:$I$41,0) -> 22 | K7: =SUMIF($J$2:$J$41,"<="&J7,$I$2:$I$41)/SUM($I$2:$I$41) -> 0.70886494 | L7: =IF(K7<=0.7,"A",IF(K7<=0.9,"B","C")) -> B | M7: =I7-(D7*F7) -> 7067000 | N7: =C7*F7 -> 13870000 | O7: =IFERROR(ROUND(M7/N7,2),"Missing") -> 0.51 | P7: =IF(O7>=2,"A",IF(O7>=1,"B","C")) -> C | R7: Class B | S7: 12 | T7: 13
A8: PRD-007 | B8: Olive Sweatshirt | C8: =IFERROR(_xlfn.XLOOKUP(A8,Table2[SKU_Code],Table2[Received_Qty]),"Missing") -> 135 | D8: =IFERROR(SUMIF(Table4[SKU_Code], A8, Table4[Qty]), "Missing") -> 58 | E8: =IFERROR(D8/C8,"Missing") -> 0.42962963 | F8: =IFERROR(_xlfn.XLOOKUP(A8, Table1[SKU_Code], Table1[Cost_IRR]), "Missing") -> 95000 | G8: =IFERROR(_xlfn.XLOOKUP(A8,Table1[SKU_Code],Table1[RRP_IRR]),"Missing") -> 215000 | H8: =IFERROR((G8-F8)/G8, "Missing") -> 0.55813953 | I8: =SUMIF(Table4[SKU_Code],'Financial Analysis'!A8,Table4[Revenue]) -> 12018500 | J8: =_xlfn.RANK.EQ(I8,$I$2:$I$41,0) -> 24 | K8: =SUMIF($J$2:$J$41,"<="&J8,$I$2:$I$41)/SUM($I$2:$I$41) -> 0.75004131 | L8: =IF(K8<=0.7,"A",IF(K8<=0.9,"B","C")) -> B | M8: =I8-(D8*F8) -> 6508500 | N8: =C8*F8 -> 12825000 | O8: =IFERROR(ROUND(M8/N8,2),"Missing") -> 0.51 | P8: =IF(O8>=2,"A",IF(O8>=1,"B","C")) -> C | R8: Class C | S8: 8 | T8: 22
A9: PRD-008 | B9: Olive Sweatshirt | C9: =IFERROR(_xlfn.XLOOKUP(A9,Table2[SKU_Code],Table2[Received_Qty]),"Missing") -> 119 | D9: =IFERROR(SUMIF(Table4[SKU_Code], A9, Table4[Qty]), "Missing") -> 74 | E9: =IFERROR(D9/C9,"Missing") -> 0.62184874 | F9: =IFERROR(_xlfn.XLOOKUP(A9, Table1[SKU_Code], Table1[Cost_IRR]), "Missing") -> 95000 | G9: =IFERROR(_xlfn.XLOOKUP(A9,Table1[SKU_Code],Table1[RRP_IRR]),"Missing") -> 215000 | H9: =IFERROR((G9-F9)/G9, "Missing") -> 0.55813953 | I9: =SUMIF(Table4[SKU_Code],'Financial Analysis'!A9,Table4[Revenue]) -> 15544500 | J9: =_xlfn.RANK.EQ(I9,$I$2:$I$41,0) -> 14 | K9: =SUMIF($J$2:$J$41,"<="&J9,$I$2:$I$41)/SUM($I$2:$I$41) -> 0.52449596 | L9: =IF(K9<=0.7,"A",IF(K9<=0.9,"B","C")) -> A | M9: =I9-(D9*F9) -> 8514500 | N9: =C9*F9 -> 11305000 | O9: =IFERROR(ROUND(M9/N9,2),"Missing") -> 0.75 | P9: =IF(O9>=2,"A",IF(O9>=1,"B","C")) -> C
A10: PRD-009 | B10: Red Sweatshirt | C10: =IFERROR(_xlfn.XLOOKUP(A10,Table2[SKU_Code],Table2[Received_Qty]),"Missing") -> 58 | D10: =IFERROR(SUMIF(Table4[SKU_Code], A10, Table4[Qty]), "Missing") -> 71 | E10: =IFERROR(D10/C10,"Missing") -> 1.2241379 | F10: =IFERROR(_xlfn.XLOOKUP(A10, Table1[SKU_Code], Table1[Cost_IRR]), "Missing") -> 95000 | G10: =IFERROR(_xlfn.XLOOKUP(A10,Table1[SKU_Code],Table1[RRP_IRR]),"Missing") -> 210000 | H10: =IFERROR((G10-F10)/G10, "Missing") -> 0.54761905 | I10: =SUMIF(Table4[SKU_Code],'Financial Analysis'!A10,Table4[Revenue]) -> 14374500 | J10: =_xlfn.RANK.EQ(I10,$I$2:$I$41,0) -> 15 | K10: =SUMIF($J$2:$J$41,"<="&J10,$I$2:$I$41)/SUM($I$2:$I$41) -> 0.5487071 | L10: =IF(K10<=0.7,"A",IF(K10<=0.9,"B","C")) -> A | M10: =I10-(D10*F10) -> 7629500 | N10: =C10*F10 -> 5510000 | O10: =IFERROR(ROUND(M10/N10,2),"Missing") -> 1.38 | P10: =IF(O10>=2,"A",IF(O10>=1,"B","C")) -> B
A11: PRD-010 | B11: Blue Sweatshirt | C11: =IFERROR(_xlfn.XLOOKUP(A11,Table2[SKU_Code],Table2[Received_Qty]),"Missing") -> 95 | D11: =IFERROR(SUMIF(Table4[SKU_Code], A11, Table4[Qty]), "Missing") -> 40 | E11: =IFERROR(D11/C11,"Missing") -> 0.42105263 | F11: =IFERROR(_xlfn.XLOOKUP(A11, Table1[SKU_Code], Table1[Cost_IRR]), "Missing") -> 95000 | G11: =IFERROR(_xlfn.XLOOKUP(A11,Table1[SKU_Code],Table1[RRP_IRR]),"Missing") -> 210000 | H11: =IFERROR((G11-F11)/G11, "Missing") -> 0.54761905 | I11: =SUMIF(Table4[SKU_Code],'Financial Analysis'!A11,Table4[Revenue]) -> 8242500 | J11: =_xlfn.RANK.EQ(I11,$I$2:$I$41,0) -> 36 | K11: =SUMIF($J$2:$J$41,"<="&J11,$I$2:$I$41)/SUM($I$2:$I$41) -> 0.95301317 | L11: =IF(K11<=0.7,"A",IF(K11<=0.9,"B","C")) -> C | M11: =I11-(D11*F11) -> 4442500 | N11: =C11*F11 -> 9025000 | O11: =IFERROR(ROUND(M11/N11,2),"Missing") -> 0.49 | P11: =IF(O11>=2,"A",IF(O11>=1,"B","C")) -> C
A12: PRD-011 | B12: Burgundy Knit Dress | C12: =IFERROR(_xlfn.XLOOKUP(A12,Table2[SKU_Code],Table2[Received_Qty]),"Missing") -> 92 | D12: =IFERROR(SUMIF(Table4[SKU_Code], A12, Table4[Qty]), "Missing") -> 38 | E12: =IFERROR(D12/C12,"Missing") -> 0.41304348 | F12: =IFERROR(_xlfn.XLOOKUP(A12, Table1[SKU_Code], Table1[Cost_IRR]), "Missing") -> 140000 | G12: =IFERROR(_xlfn.XLOOKUP(A12,Table1[SKU_Code],Table1[RRP_IRR]),"Missing") -> 320000 | H12: =IFERROR((G12-F12)/G12, "Missing") -> 0.5625 | I12: =SUMIF(Table4[SKU_Code],'Financial Analysis'!A12,Table4[Revenue]) -> 11920000 | J12: =_xlfn.RANK.EQ(I12,$I$2:$I$41,0) -> 26 | K12: =SUMIF($J$2:$J$41,"<="&J12,$I$2:$I$41)/SUM($I$2:$I$41) -> 0.79028162 | L12: =IF(K12<=0.7,"A",IF(K12<=0.9,"B","C")) -> B | M12: =I12-(D12*F12) -> 6600000 | N12: =C12*F12 -> 12880000 | O12: =IFERROR(ROUND(M12/N12,2),"Missing") -> 0.51 | P12: =IF(O12>=2,"A",IF(O12>=1,"B","C")) -> C
A13: PRD-012 | B13: Burgundy Knit Dress | C13: =IFERROR(_xlfn.XLOOKUP(A13,Table2[SKU_Code],Table2[Received_Qty]),"Missing") -> 139 | D13: =IFERROR(SUMIF(Table4[SKU_Code], A13, Table4[Qty]), "Missing") -> 42 | E13: =IFERROR(D13/C13,"Missing") -> 0.30215827 | F13: =IFERROR(_xlfn.XLOOKUP(A13, Table1[SKU_Code], Table1[Cost_IRR]), "Missing") -> 140000 | G13: =IFERROR(_xlfn.XLOOKUP(A13,Table1[SKU_Code],Table1[RRP_IRR]),"Missing") -> 320000 | H13: =IFERROR((G13-F13)/G13, "Missing") -> 0.5625 | I13: =SUMIF(Table4[SKU_Code],'Financial Analysis'!A13,Table4[Revenue]) -> 13184000 | J13: =_xlfn.RANK.EQ(I13,$I$2:$I$41,0) -> 21 | K13: =SUMIF($J$2:$J$41,"<="&J13,$I$2:$I$41)/SUM($I$2:$I$41) -> 0.68752134 | L13: =IF(K13<=0.7,"A",IF(K13<=0.9,"B","C")) -> A | M13: =I13-(D13*F13) -> 7304000 | N13: =C13*F13 -> 19460000 | O13: =IFERROR(ROUND(M13/N13,2),"Missing") -> 0.38 | P13: =IF(O13>=2,"A",IF(O13>=1,"B","C")) -> C
A14: PRD-013 | B14: Brown Turtleneck Knit | C14: =IFERROR(_xlfn.XLOOKUP(A14,Table2[SKU_Code],Table2[Received_Qty]),"Missing") -> 46 | D14: =IFERROR(SUMIF(Table4[SKU_Code], A14, Table4[Qty]), "Missing") -> 61 | E14: =IFERROR(D14/C14,"Missing") -> 1.326087 | F14: =IFERROR(_xlfn.XLOOKUP(A14, Table1[SKU_Code], Table1[Cost_IRR]), "Missing") -> 120000 | G14: =IFERROR(_xlfn.XLOOKUP(A14,Table1[SKU_Code],Table1[RRP_IRR]),"Missing") -> 280000 | H14: =IFERROR((G14-F14)/G14, "Missing") -> 0.57142857 | I14: =SUMIF(Table4[SKU_Code],'Financial Analysis'!A14,Table4[Revenue]) -> 16478000 | J14: =_xlfn.RANK.EQ(I14,$I$2:$I$41,0) -> 13 | K14: =SUMIF($J$2:$J$41,"<="&J14,$I$2:$I$41)/SUM($I$2:$I$41) -> 0.49831417 | L14: =IF(K14<=0.7,"A",IF(K14<=0.9,"B","C")) -> A | M14: =I14-(D14*F14) -> 9158000 | N14: =C14*F14 -> 5520000 | O14: =IFERROR(ROUND(M14/N14,2),"Missing") -> 1.66 | P14: =IF(O14>=2,"A",IF(O14>=1,"B","C")) -> B
A15: PRD-014 | B15: Cable Knit Vest White | C15: =IFERROR(_xlfn.XLOOKUP(A15,Table2[SKU_Code],Table2[Received_Qty]),"Missing") -> 62 | D15: =IFERROR(SUMIF(Table4[SKU_Code], A15, Table4[Qty]), "Missing") -> 55 | E15: =IFERROR(D15/C15,"Missing") -> 0.88709677 | F15: =IFERROR(_xlfn.XLOOKUP(A15, Table1[SKU_Code], Table1[Cost_IRR]), "Missing") -> 110000 | G15: =IFERROR(_xlfn.XLOOKUP(A15,Table1[SKU_Code],Table1[RRP_IRR]),"Missing") -> 260000 | H15: =IFERROR((G15-F15)/G15, "Missing") -> 0.57692308 | I15: =SUMIF(Table4[SKU_Code],'Financial Analysis'!A15,Table4[Revenue]) -> 13897000 | J15: =_xlfn.RANK.EQ(I15,$I$2:$I$41,0) -> 18 | K15: =SUMIF($J$2:$J$41,"<="&J15,$I$2:$I$41)/SUM($I$2:$I$41) -> 0.61980148 | L15: =IF(K15<=0.7,"A",IF(K15<=0.9,"B","C")) -> A | M15: =I15-(D15*F15) -> 7847000 | N15: =C15*F15 -> 6820000 | O15: =IFERROR(ROUND(M15/N15,2),"Missing") -> 1.15 | P15: =IF(O15>=2,"A",IF(O15>=1,"B","C")) -> B
A16: PRD-015 | B16: Cable Knit Vest White | C16: =IFERROR(_xlfn.XLOOKUP(A16,Table2[SKU_Code],Table2[Received_Qty]),"Missing") -> 37 | D16: =IFERROR(SUMIF(Table4[SKU_Code], A16, Table4[Qty]), "Missing") -> 43 | E16: =IFERROR(D16/C16,"Missing") -> 1.1621622 | F16: =IFERROR(_xlfn.XLOOKUP(A16, Table1[SKU_Code], Table1[Cost_IRR]), "Missing") -> 110000 | G16: =IFERROR(_xlfn.XLOOKUP(A16,Table1[SKU_Code],Table1[RRP_IRR]),"Missing") -> 260000 | H16: =IFERROR((G16-F16)/G16, "Missing") -> 0.57692308 | I16: =SUMIF(Table4[SKU_Code],'Financial Analysis'!A16,Table4[Revenue]) -> 11115000 | J16: =_xlfn.RANK.EQ(I16,$I$2:$I$41,0) -> 27 | K16: =SUMIF($J$2:$J$41,"<="&J16,$I$2:$I$41)/SUM($I$2:$I$41) -> 0.80900275 | L16: =IF(K16<=0.7,"A",IF(K16<=0.9,"B","C")) -> B | M16: =I16-(D16*F16) -> 6385000 | N16: =C16*F16 -> 4070000 | O16: =IFERROR(ROUND(M16/N16,2),"Missing") -> 1.57 | P16: =IF(O16>=2,"A",IF(O16>=1,"B","C")) -> B
A17: PRD-016 | B17: Grey Hoodie | C17: =IFERROR(_xlfn.XLOOKUP(A17,Table2[SKU_Code],Table2[Received_Qty]),"Missing") -> 38 | D17: =IFERROR(SUMIF(Table4[SKU_Code], A17, Table4[Qty]), "Missing") -> 39 | E17: =IFERROR(D17/C17,"Missing") -> 1.0263158 | F17: =IFERROR(_xlfn.XLOOKUP(A17, Table1[SKU_Code], Table1[Cost_IRR]), "Missing") -> 105000 | G17: =IFERROR(_xlfn.XLOOKUP(A17,Table1[SKU_Code],Table1[RRP_IRR]),"Missing") -> 235000 | H17: =IFERROR((G17-F17)/G17, "Missing") -> 0.55319149 | I17: =SUMIF(Table4[SKU_Code],'Financial Analysis'!A17,Table4[Revenue]) -> 8988750 | J17: =_xlfn.RANK.EQ(I17,$I$2:$I$41,0) -> 33 | K17: =SUMIF($J$2:$J$41,"<="&J17,$I$2:$I$41)/SUM($I$2:$I$41) -> 0.91069231 | L17: =IF(K17<=0.7,"A",IF(K17<=0.9,"B","C")) -> C | M17: =I17-(D17*F17) -> 4893750 | N17: =C17*F17 -> 3990000 | O17: =IFERROR(ROUND(M17/N17,2),"Missing") -> 1.23 | P17: =IF(O17>=2,"A",IF(O17>=1,"B","C")) -> B
